{
 "cells": [
  {
   "cell_type": "code",
   "execution_count": 23,
   "metadata": {},
   "outputs": [
    {
     "name": "stdout",
     "output_type": "stream",
     "text": [
      " * Serving Flask app \"__main__\" (lazy loading)\n",
      " * Environment: production\n",
      "\u001b[31m   WARNING: This is a development server. Do not use it in a production deployment.\u001b[0m\n",
      "\u001b[2m   Use a production WSGI server instead.\u001b[0m\n",
      " * Debug mode: off\n"
     ]
    },
    {
     "name": "stderr",
     "output_type": "stream",
     "text": [
      " * Running on http://0.0.0.0:5000/ (Press CTRL+C to quit)\n",
      "INFO:werkzeug: * Running on http://0.0.0.0:5000/ (Press CTRL+C to quit)\n",
      "[2020-11-11 15:38:25,414] ERROR in app: Exception on / [GET]\n",
      "Traceback (most recent call last):\n",
      "  File \"/usr/local/Cellar/jupyterlab/2.2.8/libexec/lib/python3.8/site-packages/flask/app.py\", line 2447, in wsgi_app\n",
      "    response = self.full_dispatch_request()\n",
      "  File \"/usr/local/Cellar/jupyterlab/2.2.8/libexec/lib/python3.8/site-packages/flask/app.py\", line 1952, in full_dispatch_request\n",
      "    rv = self.handle_user_exception(e)\n",
      "  File \"/usr/local/Cellar/jupyterlab/2.2.8/libexec/lib/python3.8/site-packages/flask_cors/extension.py\", line 165, in wrapped_function\n",
      "    return cors_after_request(app.make_response(f(*args, **kwargs)))\n",
      "  File \"/usr/local/Cellar/jupyterlab/2.2.8/libexec/lib/python3.8/site-packages/flask/app.py\", line 1821, in handle_user_exception\n",
      "    reraise(exc_type, exc_value, tb)\n",
      "  File \"/usr/local/Cellar/jupyterlab/2.2.8/libexec/lib/python3.8/site-packages/flask/_compat.py\", line 39, in reraise\n",
      "    raise value\n",
      "  File \"/usr/local/Cellar/jupyterlab/2.2.8/libexec/lib/python3.8/site-packages/flask/app.py\", line 1950, in full_dispatch_request\n",
      "    rv = self.dispatch_request()\n",
      "  File \"/usr/local/Cellar/jupyterlab/2.2.8/libexec/lib/python3.8/site-packages/flask/app.py\", line 1936, in dispatch_request\n",
      "    return self.view_functions[rule.endpoint](**req.view_args)\n",
      "  File \"<ipython-input-23-dade5b6e6a7b>\", line 15, in test_router\n",
      "    my_logger.info(\"hello this is root url!\")\n",
      "NameError: name 'my_logger' is not defined\n",
      "ERROR:__main__:Exception on / [GET]\n",
      "Traceback (most recent call last):\n",
      "  File \"/usr/local/Cellar/jupyterlab/2.2.8/libexec/lib/python3.8/site-packages/flask/app.py\", line 2447, in wsgi_app\n",
      "    response = self.full_dispatch_request()\n",
      "  File \"/usr/local/Cellar/jupyterlab/2.2.8/libexec/lib/python3.8/site-packages/flask/app.py\", line 1952, in full_dispatch_request\n",
      "    rv = self.handle_user_exception(e)\n",
      "  File \"/usr/local/Cellar/jupyterlab/2.2.8/libexec/lib/python3.8/site-packages/flask_cors/extension.py\", line 165, in wrapped_function\n",
      "    return cors_after_request(app.make_response(f(*args, **kwargs)))\n",
      "  File \"/usr/local/Cellar/jupyterlab/2.2.8/libexec/lib/python3.8/site-packages/flask/app.py\", line 1821, in handle_user_exception\n",
      "    reraise(exc_type, exc_value, tb)\n",
      "  File \"/usr/local/Cellar/jupyterlab/2.2.8/libexec/lib/python3.8/site-packages/flask/_compat.py\", line 39, in reraise\n",
      "    raise value\n",
      "  File \"/usr/local/Cellar/jupyterlab/2.2.8/libexec/lib/python3.8/site-packages/flask/app.py\", line 1950, in full_dispatch_request\n",
      "    rv = self.dispatch_request()\n",
      "  File \"/usr/local/Cellar/jupyterlab/2.2.8/libexec/lib/python3.8/site-packages/flask/app.py\", line 1936, in dispatch_request\n",
      "    return self.view_functions[rule.endpoint](**req.view_args)\n",
      "  File \"<ipython-input-23-dade5b6e6a7b>\", line 15, in test_router\n",
      "    my_logger.info(\"hello this is root url!\")\n",
      "NameError: name 'my_logger' is not defined\n",
      "127.0.0.1 - - [11/Nov/2020 15:38:25] \"\u001b[35m\u001b[1mGET / HTTP/1.1\u001b[0m\" 500 -\n",
      "INFO:werkzeug:127.0.0.1 - - [11/Nov/2020 15:38:25] \"\u001b[35m\u001b[1mGET / HTTP/1.1\u001b[0m\" 500 -\n"
     ]
    }
   ],
   "source": [
    "import os\n",
    "\n",
    "from flask import Flask, request, abort, jsonify, send_from_directory\n",
    "\n",
    "\n",
    "UPLOAD_DIRECTORY = '/project/api_uploaded_files'\n",
    "\n",
    "if not os.path.exists(UPLOAD_DIRECTORY):\n",
    "    os.makedirs(UPLOAD_DIRECTORY)\n",
    "\n",
    "\n",
    "api = Flask(__name__)\n",
    "\n",
    "\n",
    "@api.route('/files/<path:path>')\n",
    "def get_file(path):\n",
    "    \"\"\"Download a file.\"\"\"\n",
    "    return send_from_directory(UPLOAD_DIRECTORY, path, as_attachment=True)"
   ]
  },
  {
   "cell_type": "code",
   "execution_count": 17,
   "metadata": {},
   "outputs": [
    {
     "name": "stdout",
     "output_type": "stream",
     "text": [
      "\u001b[31mERROR: Could not find a version that satisfies the requirement CORS (from versions: none)\u001b[0m\n",
      "\u001b[31mERROR: No matching distribution found for CORS\u001b[0m\n",
      "\u001b[33mWARNING: You are using pip version 20.2.3; however, version 20.2.4 is available.\n",
      "You should consider upgrading via the '/usr/local/Cellar/jupyterlab/2.2.8/libexec/bin/python3.8 -m pip install --upgrade pip' command.\u001b[0m\n",
      "Note: you may need to restart the kernel to use updated packages.\n"
     ]
    }
   ],
   "source": [
    "pip install CORS"
   ]
  },
  {
   "cell_type": "code",
   "execution_count": 22,
   "metadata": {},
   "outputs": [
    {
     "name": "stdout",
     "output_type": "stream",
     "text": [
      "\u001b[31mERROR: Could not find a version that satisfies the requirement my_util.my_logger (from versions: none)\u001b[0m\n",
      "\u001b[31mERROR: No matching distribution found for my_util.my_logger\u001b[0m\n",
      "\u001b[33mWARNING: You are using pip version 20.2.3; however, version 20.2.4 is available.\n",
      "You should consider upgrading via the '/usr/local/Cellar/jupyterlab/2.2.8/libexec/bin/python3.8 -m pip install --upgrade pip' command.\u001b[0m\n",
      "Note: you may need to restart the kernel to use updated packages.\n"
     ]
    }
   ],
   "source": [
    "pip install my_util.my_logger"
   ]
  },
  {
   "cell_type": "code",
   "execution_count": null,
   "metadata": {},
   "outputs": [],
   "source": []
  }
 ],
 "metadata": {
  "kernelspec": {
   "display_name": "Python 3",
   "language": "python",
   "name": "python3"
  },
  "language_info": {
   "codemirror_mode": {
    "name": "ipython",
    "version": 3
   },
   "file_extension": ".py",
   "mimetype": "text/x-python",
   "name": "python",
   "nbconvert_exporter": "python",
   "pygments_lexer": "ipython3",
   "version": "3.8.5"
  }
 },
 "nbformat": 4,
 "nbformat_minor": 4
}
